<?xml version="1.0"?>
<robot xmlns:xacro="http://www.ros.org/wiki/xacro">
    <link
        name="Link_Left_Fan">
        <inertial>
            <origin
                xyz="2.77555756156289E-16 0.0203953252144142 -2.22044604925031E-16"
                rpy="0 0 0" />
            <mass
                value="0.825243626112144" />
            <inertia
                ixx="0.00759152180746469"
                ixy="-2.67963842023617E-18"
                ixz="1.51788304147971E-18"
                iyy="0.0142303156032698"
                iyz="6.36750627774146E-18"
                izz="0.00759152180746468" />
        </inertial>
        <visual>
            <origin
                xyz="0 0 0"
                rpy="0 0 0" />
            <geometry>
                <mesh
                    filename="file://$(find shippy)/meshes/Link_Left_Fan.STL" />
            </geometry>
            <material
                name="">
                <color
                    rgba="0.780392156862745 0.76078431372549 0.741176470588235 1" />
            </material>
        </visual>
        <collision>
            <origin
                xyz="0 0 0"
                rpy="0 0 0" />
            <geometry>
                <mesh
                    filename="file://$(find shippy)/meshes/Link_Left_Fan.STL" />
            </geometry>
        </collision>
    </link>
    <gazebo reference="Link_Left_Fan">
        <material>Gazebo/Indigo</material>
    </gazebo>
    <joint
        name="Joint_Left_Fan"
        type="continuous">
        <origin
            xyz="-0.315 0.3 -0.15"
            rpy="3.1416 -0.98049 1.5708" />
        <parent
            link="base_link_reference" />
        <child
            link="Link_Left_Fan" />
        <axis
            xyz="0 -1 0" />
    </joint>
    <link
        name="Link_Right_Fan">
        <inertial>
            <origin
                xyz="0 0.0203953252144143 0"
                rpy="0 0 0" />
            <mass
                value="0.825243626112141" />
            <inertia
                ixx="0.00759152180746467"
                ixy="-2.0574745116365E-18"
                ixz="-5.63785129692462E-18"
                iyy="0.0142303156032698"
                iyz="2.2547798391998E-18"
                izz="0.00759152180746466" />
        </inertial>
        <visual>
            <origin
                xyz="0 0 0"
                rpy="0 0 0" />
            <geometry>
                <mesh
                    filename="file://$(find shippy)/meshes/Link_Right_Fan.STL" />
            </geometry>
            <material
                name="">
                <color
                    rgba="0.780392156862745 0.76078431372549 0.741176470588235 1" />
            </material>
        </visual>
        <collision>
            <origin
                xyz="0 0 0"
                rpy="0 0 0" />
            <geometry>
                <mesh
                    filename="file://$(find shippy)/meshes/Link_Right_Fan.STL" />
            </geometry>
        </collision>
    </link>
    <gazebo reference="Link_Right_Fan">
        <material>Gazebo/Indigo</material>
    </gazebo>
    <joint
        name="Joint_Right_Fan"
        type="continuous">
        <origin
            xyz="0.315 0.3 -0.15"
            rpy="3.1416 1.2132 -1.5708" />
        <parent
            link="base_link_reference" />
        <child
            link="Link_Right_Fan" />
        <axis
            xyz="0 1 0" />
    </joint>
</robot>